Process Process-4:
Traceback (most recent call last):
  File "/home/rtcalumby/miniconda3/envs/fgdcc/lib/python3.9/multiprocessing/process.py", line 315, in _bootstrap
    self.run()
  File "/home/rtcalumby/miniconda3/envs/fgdcc/lib/python3.9/multiprocessing/process.py", line 108, in run
    self._target(*self._args, **self._kwargs)
  File "/home/rtcalumby/adam/luciano/PlantCLEF2025/PlantCLEF2025/main.py", line 35, in process_main
    with open(args.fname, 'r') as y_file:
NameError: name 'args' is not defined
Process Process-3:
Traceback (most recent call last):
  File "/home/rtcalumby/miniconda3/envs/fgdcc/lib/python3.9/multiprocessing/process.py", line 315, in _bootstrap
    self.run()
  File "/home/rtcalumby/miniconda3/envs/fgdcc/lib/python3.9/multiprocessing/process.py", line 108, in run
    self._target(*self._args, **self._kwargs)
  File "/home/rtcalumby/adam/luciano/PlantCLEF2025/PlantCLEF2025/main.py", line 35, in process_main
    with open(args.fname, 'r') as y_file:
NameError: name 'args' is not defined
Process Process-2:
Traceback (most recent call last):
  File "/home/rtcalumby/miniconda3/envs/fgdcc/lib/python3.9/multiprocessing/process.py", line 315, in _bootstrap
    self.run()
  File "/home/rtcalumby/miniconda3/envs/fgdcc/lib/python3.9/multiprocessing/process.py", line 108, in run
    self._target(*self._args, **self._kwargs)
  File "/home/rtcalumby/adam/luciano/PlantCLEF2025/PlantCLEF2025/main.py", line 35, in process_main
    with open(args.fname, 'r') as y_file:
NameError: name 'args' is not defined
INFO:root:called-params config/configs.yaml
Process Process-1:
Traceback (most recent call last):
  File "/home/rtcalumby/miniconda3/envs/fgdcc/lib/python3.9/multiprocessing/process.py", line 315, in _bootstrap
    self.run()
  File "/home/rtcalumby/miniconda3/envs/fgdcc/lib/python3.9/multiprocessing/process.py", line 108, in run
    self._target(*self._args, **self._kwargs)
  File "/home/rtcalumby/adam/luciano/PlantCLEF2025/PlantCLEF2025/main.py", line 35, in process_main
    with open(args.fname, 'r') as y_file:
NameError: name 'args' is not defined
