INFO:root:called-params config/configs.yaml
INFO:root:loaded params...
INFO:root:{'k_means': {'K': 7806}, 'patches': {'N': [16, 32, 64, 80, 128]}, 'num_workers': 32, 'base_dir': '/home/rtcalumby/adam/luciano/PlantCLEF2025/PlantCLEF2025/', 'pretrained_path': 'pretrained_models/vit_base_patch14_reg4_dinov2_lvd142m_pc24_onlyclassifier_then_all/model_best.pth.tar', 'data': {'class_mapping': 'pretrained_models/class_mapping.txt', 'species_mapping': 'pretrained_models/species_id_to_name.txt', 'test_data': '/home/rtcalumby/adam/luciano/PlantCLEF2025/test_dataset/'}}
INFO:root:Running... (rank: 0/1)
Process Process-1:
Traceback (most recent call last):
  File "/home/rtcalumby/miniconda3/envs/fgdcc/lib/python3.9/multiprocessing/process.py", line 315, in _bootstrap
    self.run()
  File "/home/rtcalumby/miniconda3/envs/fgdcc/lib/python3.9/multiprocessing/process.py", line 108, in run
    self._target(*self._args, **self._kwargs)
  File "/home/rtcalumby/adam/luciano/PlantCLEF2025/PlantCLEF2025/main_feature_extraction.py", line 44, in process_main
    app_main(args=params)
  File "/home/rtcalumby/adam/luciano/PlantCLEF2025/PlantCLEF2025/engine_feature_extraction.py", line 43, in main
    train_dir = args['data']['train_data']
KeyError: 'train_data'
