INFO:root:called-params config/feature_extraction.yaml
INFO:root:loaded params...
INFO:root:{'num_workers': 64, 'base_dir': '/home/rtcalumby/adam/luciano/PlantCLEF2025/PlantCLEF2025/', 'pretrained_path': 'pretrained_models/vit_base_patch14_reg4_dinov2_lvd142m_pc24_onlyclassifier_then_all/model_best.pth.tar', 'data': {'class_mapping': 'pretrained_models/class_mapping.txt', 'species_mapping': 'pretrained_models/species_id_to_name.txt', 'train_data': '/home/rtcalumby/adam/luciano/PlantCLEF2025/images_max_side_800/', 'output_dir': '/home/rtcalumby/adam/luciano/PlantCLEF2025/cached_features/'}}
INFO:root:Running... (rank: 0/8)
INFO:root:Initialized (rank/world-size) 0/8
INFO:timm.models._helpers:Loaded state_dict_ema from checkpoint 'pretrained_models/vit_base_patch14_reg4_dinov2_lvd142m_pc24_onlyclassifier_then_all/model_best.pth.tar'
Train dataset created for rank 0,/8
Data Loader length: 86 process_id: 0
Train dataset created for rank 2,/8
Data Loader length: 86 process_id: 2
Train dataset created for rank 3,/8
Data Loader length: 86 process_id: 3
Train dataset created for rank 5,/8
Data Loader length: 86 process_id: 5
Train dataset created for rank 4,/8
Data Loader length: 86 process_id: 4
terminate called after throwing an instance of 'c10::DistNetworkError'
  what():  Connection reset by peer
Exception raised from recvBytes at /opt/conda/conda-bld/pytorch_1712608885084/work/torch/csrc/distributed/c10d/Utils.hpp:672 (most recent call first):
frame #0: c10::Error::Error(c10::SourceLocation, std::string) + 0x57 (0x7f5ac0b78897 in /home/rtcalumby/miniconda3/envs/fgdcc/lib/python3.9/site-packages/torch/lib/libc10.so)
frame #1: <unknown function> + 0x57c69fe (0x7f5b19ee99fe in /home/rtcalumby/miniconda3/envs/fgdcc/lib/python3.9/site-packages/torch/lib/libtorch_cpu.so)
frame #2: c10d::TCPStore::check(std::vector<std::string, std::allocator<std::string> > const&) + 0x2d8 (0x7f5b19ee5538 in /home/rtcalumby/miniconda3/envs/fgdcc/lib/python3.9/site-packages/torch/lib/libtorch_cpu.so)
frame #3: c10d::ProcessGroupNCCL::heartbeatMonitor() + 0x34d (0x7f5ac1e466fd in /home/rtcalumby/miniconda3/envs/fgdcc/lib/python3.9/site-packages/torch/lib/libtorch_cuda.so)
frame #4: <unknown function> + 0xd3b65 (0x7f5b223e3b65 in /home/rtcalumby/miniconda3/envs/fgdcc/lib/python3.9/site-packages/torch/lib/../../../.././libstdc++.so.6)
frame #5: <unknown function> + 0x8609 (0x7f5b2b294609 in /lib/x86_64-linux-gnu/libpthread.so.0)
frame #6: clone + 0x43 (0x7f5b2b05f353 in /lib/x86_64-linux-gnu/libc.so.6)

Train dataset created for rank 6,/8
Data Loader length: 86 process_id: 6
Train dataset created for rank 7,/8
Data Loader length: 86 process_id: 7
Train dataset created for rank 1,/8
Data Loader length: 86 process_id: 1
terminate called after throwing an instance of 'c10::DistNetworkError'
  what():  Connection reset by peer
Exception raised from recvBytes at /opt/conda/conda-bld/pytorch_1712608885084/work/torch/csrc/distributed/c10d/Utils.hpp:672 (most recent call first):
frame #0: c10::Error::Error(c10::SourceLocation, std::string) + 0x57 (0x7fbe35d2e897 in /home/rtcalumby/miniconda3/envs/fgdcc/lib/python3.9/site-packages/torch/lib/libc10.so)
frame #1: <unknown function> + 0x57c69fe (0x7fbe8f09f9fe in /home/rtcalumby/miniconda3/envs/fgdcc/lib/python3.9/site-packages/torch/lib/libtorch_cpu.so)
frame #2: c10d::TCPStore::check(std::vector<std::string, std::allocator<std::string> > const&) + 0x2d8 (0x7fbe8f09b538 in /home/rtcalumby/miniconda3/envs/fgdcc/lib/python3.9/site-packages/torch/lib/libtorch_cpu.so)
frame #3: c10d::ProcessGroupNCCL::heartbeatMonitor() + 0x34d (0x7fbe36ffc6fd in /home/rtcalumby/miniconda3/envs/fgdcc/lib/python3.9/site-packages/torch/lib/libtorch_cuda.so)
frame #4: <unknown function> + 0xd3b65 (0x7fbe97599b65 in /home/rtcalumby/miniconda3/envs/fgdcc/lib/python3.9/site-packages/torch/lib/../../../.././libstdc++.so.6)
frame #5: <unknown function> + 0x8609 (0x7fbea044a609 in /lib/x86_64-linux-gnu/libpthread.so.0)
frame #6: clone + 0x43 (0x7fbea0215353 in /lib/x86_64-linux-gnu/libc.so.6)

