INFO:root:called-params config/configs.yaml
INFO:root:loaded params...
INFO:root:{'k_means': {'K': 7806}, 'patches': {'N': [16, 32, 64, 80, 128]}, 'num_workers': 32, 'base_dir': '/home/rtcalumby/adam/luciano/PlantCLEF2025/PlantCLEF2025/', 'pretrained_path': 'pretrained_models/vit_base_patch14_reg4_dinov2_lvd142m_pc24_onlyclassifier_then_all/model_best.pth.tar', 'data': {'class_mapping': 'pretrained_models/class_mapping.txt', 'species_mapping': 'pretrained_models/species_id_to_name.txt', 'test_data': '/home/rtcalumby/adam/luciano/PlantCLEF2025/test_dataset/'}}
INFO:root:Running... (rank: 0/4)
INFO:root:Initialized (rank/world-size) 0/4
Process Process-2:
Traceback (most recent call last):
  File "/home/rtcalumby/miniconda3/envs/fgdcc/lib/python3.9/multiprocessing/process.py", line 315, in _bootstrap
    self.run()
  File "/home/rtcalumby/miniconda3/envs/fgdcc/lib/python3.9/multiprocessing/process.py", line 108, in run
    self._target(*self._args, **self._kwargs)
  File "/home/rtcalumby/adam/luciano/PlantCLEF2025/PlantCLEF2025/main.py", line 44, in process_main
    app_main(args=params)
  File "/home/rtcalumby/adam/luciano/PlantCLEF2025/PlantCLEF2025/engine_baseline.py", line 68, in main
    model = model.to(device)
  File "/home/rtcalumby/miniconda3/envs/fgdcc/lib/python3.9/site-packages/torch/nn/modules/module.py", line 1173, in to
    return self._apply(convert)
  File "/home/rtcalumby/miniconda3/envs/fgdcc/lib/python3.9/site-packages/torch/nn/modules/module.py", line 779, in _apply
    module._apply(fn)
  File "/home/rtcalumby/miniconda3/envs/fgdcc/lib/python3.9/site-packages/torch/nn/modules/module.py", line 779, in _apply
    module._apply(fn)
  File "/home/rtcalumby/miniconda3/envs/fgdcc/lib/python3.9/site-packages/torch/nn/modules/module.py", line 804, in _apply
    param_applied = fn(param)
  File "/home/rtcalumby/miniconda3/envs/fgdcc/lib/python3.9/site-packages/torch/nn/modules/module.py", line 1159, in convert
    return t.to(
RuntimeError: CUDA error: invalid device ordinal
CUDA kernel errors might be asynchronously reported at some other API call, so the stacktrace below might be incorrect.
For debugging consider passing CUDA_LAUNCH_BLOCKING=1.
Compile with `TORCH_USE_CUDA_DSA` to enable device-side assertions.

Process Process-3:
Traceback (most recent call last):
  File "/home/rtcalumby/miniconda3/envs/fgdcc/lib/python3.9/multiprocessing/process.py", line 315, in _bootstrap
    self.run()
  File "/home/rtcalumby/miniconda3/envs/fgdcc/lib/python3.9/multiprocessing/process.py", line 108, in run
    self._target(*self._args, **self._kwargs)
  File "/home/rtcalumby/adam/luciano/PlantCLEF2025/PlantCLEF2025/main.py", line 44, in process_main
    app_main(args=params)
  File "/home/rtcalumby/adam/luciano/PlantCLEF2025/PlantCLEF2025/engine_baseline.py", line 68, in main
    model = model.to(device)
  File "/home/rtcalumby/miniconda3/envs/fgdcc/lib/python3.9/site-packages/torch/nn/modules/module.py", line 1173, in to
    return self._apply(convert)
  File "/home/rtcalumby/miniconda3/envs/fgdcc/lib/python3.9/site-packages/torch/nn/modules/module.py", line 779, in _apply
    module._apply(fn)
  File "/home/rtcalumby/miniconda3/envs/fgdcc/lib/python3.9/site-packages/torch/nn/modules/module.py", line 779, in _apply
    module._apply(fn)
  File "/home/rtcalumby/miniconda3/envs/fgdcc/lib/python3.9/site-packages/torch/nn/modules/module.py", line 804, in _apply
    param_applied = fn(param)
  File "/home/rtcalumby/miniconda3/envs/fgdcc/lib/python3.9/site-packages/torch/nn/modules/module.py", line 1159, in convert
    return t.to(
RuntimeError: CUDA error: invalid device ordinal
CUDA kernel errors might be asynchronously reported at some other API call, so the stacktrace below might be incorrect.
For debugging consider passing CUDA_LAUNCH_BLOCKING=1.
Compile with `TORCH_USE_CUDA_DSA` to enable device-side assertions.

INFO:timm.models._helpers:Loaded state_dict_ema from checkpoint 'pretrained_models/vit_base_patch14_reg4_dinov2_lvd142m_pc24_onlyclassifier_then_all/model_best.pth.tar'
Process Process-4:
Traceback (most recent call last):
  File "/home/rtcalumby/miniconda3/envs/fgdcc/lib/python3.9/multiprocessing/process.py", line 315, in _bootstrap
    self.run()
  File "/home/rtcalumby/miniconda3/envs/fgdcc/lib/python3.9/multiprocessing/process.py", line 108, in run
    self._target(*self._args, **self._kwargs)
  File "/home/rtcalumby/adam/luciano/PlantCLEF2025/PlantCLEF2025/main.py", line 44, in process_main
    app_main(args=params)
  File "/home/rtcalumby/adam/luciano/PlantCLEF2025/PlantCLEF2025/engine_baseline.py", line 68, in main
    model = model.to(device)
  File "/home/rtcalumby/miniconda3/envs/fgdcc/lib/python3.9/site-packages/torch/nn/modules/module.py", line 1173, in to
    return self._apply(convert)
  File "/home/rtcalumby/miniconda3/envs/fgdcc/lib/python3.9/site-packages/torch/nn/modules/module.py", line 779, in _apply
    module._apply(fn)
  File "/home/rtcalumby/miniconda3/envs/fgdcc/lib/python3.9/site-packages/torch/nn/modules/module.py", line 779, in _apply
    module._apply(fn)
  File "/home/rtcalumby/miniconda3/envs/fgdcc/lib/python3.9/site-packages/torch/nn/modules/module.py", line 804, in _apply
    param_applied = fn(param)
  File "/home/rtcalumby/miniconda3/envs/fgdcc/lib/python3.9/site-packages/torch/nn/modules/module.py", line 1159, in convert
    return t.to(
RuntimeError: CUDA error: invalid device ordinal
CUDA kernel errors might be asynchronously reported at some other API call, so the stacktrace below might be incorrect.
For debugging consider passing CUDA_LAUNCH_BLOCKING=1.
Compile with `TORCH_USE_CUDA_DSA` to enable device-side assertions.

Test dataset created
slurmstepd: error: *** JOB 5469 ON hgx CANCELLED AT 2025-04-16T11:34:34 ***
