INFO:root:called-params config/configs.yaml
INFO:root:loaded params...
{   'base_dir': '/home/rtcalumby/adam/luciano/PlantCLEF2025/PlantCLEF2025/',
    'data': {   'class_mapping': 'pretrained_models/class_mapping.txt',
                'species_mapping': 'pretrained_models/species_id_to_name.txt',
                'test_data': '/home/rtcalumby/adam/luciano/PlantCLEF2025/test_dataset/'},
    'k_means': {'K': 7806},
    'num_workers': 32,
    'patches': {'N': [16, 32, 64, 80, 128]},
    'pretrained_path': 'pretrained_models/vit_base_patch14_reg4_dinov2_lvd142m_pc24_onlyclassifier_then_all/model_best.pth.tar'}
INFO:root:Running... (rank: 0/4)
INFO:root:Initialized (rank/world-size) 0/4
INFO:timm.models._helpers:Loaded state_dict_ema from checkpoint 'pretrained_models/vit_base_patch14_reg4_dinov2_lvd142m_pc24_onlyclassifier_then_all/model_best.pth.tar'
Test dataset created
{   'base_dir': '/home/rtcalumby/adam/luciano/PlantCLEF2025/PlantCLEF2025/',
    'data': {   'class_mapping': 'pretrained_models/class_mapping.txt',
                'species_mapping': 'pretrained_models/species_id_to_name.txt',
                'test_data': '/home/rtcalumby/adam/luciano/PlantCLEF2025/test_dataset/'},
    'k_means': {'K': 7806},
    'num_workers': 32,
    'patches': {'N': [16, 32, 64, 80, 128]},
    'pretrained_path': 'pretrained_models/vit_base_patch14_reg4_dinov2_lvd142m_pc24_onlyclassifier_then_all/model_best.pth.tar'}
Test dataset created
{   'base_dir': '/home/rtcalumby/adam/luciano/PlantCLEF2025/PlantCLEF2025/',
    'data': {   'class_mapping': 'pretrained_models/class_mapping.txt',
                'species_mapping': 'pretrained_models/species_id_to_name.txt',
                'test_data': '/home/rtcalumby/adam/luciano/PlantCLEF2025/test_dataset/'},
    'k_means': {'K': 7806},
    'num_workers': 32,
    'patches': {'N': [16, 32, 64, 80, 128]},
    'pretrained_path': 'pretrained_models/vit_base_patch14_reg4_dinov2_lvd142m_pc24_onlyclassifier_then_all/model_best.pth.tar'}
Test dataset created
{   'base_dir': '/home/rtcalumby/adam/luciano/PlantCLEF2025/PlantCLEF2025/',
    'data': {   'class_mapping': 'pretrained_models/class_mapping.txt',
                'species_mapping': 'pretrained_models/species_id_to_name.txt',
                'test_data': '/home/rtcalumby/adam/luciano/PlantCLEF2025/test_dataset/'},
    'k_means': {'K': 7806},
    'num_workers': 32,
    'patches': {'N': [16, 32, 64, 80, 128]},
    'pretrained_path': 'pretrained_models/vit_base_patch14_reg4_dinov2_lvd142m_pc24_onlyclassifier_then_all/model_best.pth.tar'}
Test dataset created
Process Process-1:
Traceback (most recent call last):
  File "/home/rtcalumby/miniconda3/envs/fgdcc/lib/python3.9/site-packages/torch/utils/data/dataloader.py", line 1133, in _try_get_data
    data = self._data_queue.get(timeout=timeout)
  File "/home/rtcalumby/miniconda3/envs/fgdcc/lib/python3.9/multiprocessing/queues.py", line 113, in get
    if not self._poll(timeout):
  File "/home/rtcalumby/miniconda3/envs/fgdcc/lib/python3.9/multiprocessing/connection.py", line 257, in poll
    return self._poll(timeout)
  File "/home/rtcalumby/miniconda3/envs/fgdcc/lib/python3.9/multiprocessing/connection.py", line 424, in _poll
    r = wait([self], timeout)
  File "/home/rtcalumby/miniconda3/envs/fgdcc/lib/python3.9/multiprocessing/connection.py", line 931, in wait
    ready = selector.select(timeout)
  File "/home/rtcalumby/miniconda3/envs/fgdcc/lib/python3.9/selectors.py", line 416, in select
    fd_event_list = self._selector.poll(timeout)
  File "/home/rtcalumby/miniconda3/envs/fgdcc/lib/python3.9/site-packages/torch/utils/data/_utils/signal_handling.py", line 66, in handler
    _error_if_any_worker_fails()
RuntimeError: DataLoader worker (pid 1539316) is killed by signal: Killed. 

The above exception was the direct cause of the following exception:

Traceback (most recent call last):
  File "/home/rtcalumby/miniconda3/envs/fgdcc/lib/python3.9/multiprocessing/process.py", line 315, in _bootstrap
    self.run()
  File "/home/rtcalumby/miniconda3/envs/fgdcc/lib/python3.9/multiprocessing/process.py", line 108, in run
    self._target(*self._args, **self._kwargs)
  File "/home/rtcalumby/adam/luciano/PlantCLEF2025/PlantCLEF2025/main.py", line 44, in process_main
    app_main(args=params)
  File "/home/rtcalumby/adam/luciano/PlantCLEF2025/PlantCLEF2025/engine_baseline.py", line 89, in main
    for im_id, (preprocessed_images, _, name) in enumerate(test_dataloader):
  File "/home/rtcalumby/miniconda3/envs/fgdcc/lib/python3.9/site-packages/torch/utils/data/dataloader.py", line 631, in __next__
    data = self._next_data()
  File "/home/rtcalumby/miniconda3/envs/fgdcc/lib/python3.9/site-packages/torch/utils/data/dataloader.py", line 1329, in _next_data
    idx, data = self._get_data()
  File "/home/rtcalumby/miniconda3/envs/fgdcc/lib/python3.9/site-packages/torch/utils/data/dataloader.py", line 1295, in _get_data
    success, data = self._try_get_data()
  File "/home/rtcalumby/miniconda3/envs/fgdcc/lib/python3.9/site-packages/torch/utils/data/dataloader.py", line 1146, in _try_get_data
    raise RuntimeError(f'DataLoader worker (pid(s) {pids_str}) exited unexpectedly') from e
RuntimeError: DataLoader worker (pid(s) 1539316) exited unexpectedly
Process Process-3:
Traceback (most recent call last):
  File "/home/rtcalumby/miniconda3/envs/fgdcc/lib/python3.9/site-packages/torch/utils/data/dataloader.py", line 1133, in _try_get_data
    data = self._data_queue.get(timeout=timeout)
  File "/home/rtcalumby/miniconda3/envs/fgdcc/lib/python3.9/multiprocessing/queues.py", line 113, in get
    if not self._poll(timeout):
  File "/home/rtcalumby/miniconda3/envs/fgdcc/lib/python3.9/multiprocessing/connection.py", line 257, in poll
    return self._poll(timeout)
  File "/home/rtcalumby/miniconda3/envs/fgdcc/lib/python3.9/multiprocessing/connection.py", line 424, in _poll
    r = wait([self], timeout)
  File "/home/rtcalumby/miniconda3/envs/fgdcc/lib/python3.9/multiprocessing/connection.py", line 931, in wait
    ready = selector.select(timeout)
  File "/home/rtcalumby/miniconda3/envs/fgdcc/lib/python3.9/selectors.py", line 416, in select
    fd_event_list = self._selector.poll(timeout)
  File "/home/rtcalumby/miniconda3/envs/fgdcc/lib/python3.9/site-packages/torch/utils/data/_utils/signal_handling.py", line 66, in handler
    _error_if_any_worker_fails()
RuntimeError: DataLoader worker (pid 1542685) is killed by signal: Killed. 

The above exception was the direct cause of the following exception:

Traceback (most recent call last):
  File "/home/rtcalumby/miniconda3/envs/fgdcc/lib/python3.9/multiprocessing/process.py", line 315, in _bootstrap
    self.run()
  File "/home/rtcalumby/miniconda3/envs/fgdcc/lib/python3.9/multiprocessing/process.py", line 108, in run
    self._target(*self._args, **self._kwargs)
  File "/home/rtcalumby/adam/luciano/PlantCLEF2025/PlantCLEF2025/main.py", line 44, in process_main
    app_main(args=params)
  File "/home/rtcalumby/adam/luciano/PlantCLEF2025/PlantCLEF2025/engine_baseline.py", line 89, in main
    for im_id, (preprocessed_images, _, name) in enumerate(test_dataloader):
  File "/home/rtcalumby/miniconda3/envs/fgdcc/lib/python3.9/site-packages/torch/utils/data/dataloader.py", line 631, in __next__
    data = self._next_data()
  File "/home/rtcalumby/miniconda3/envs/fgdcc/lib/python3.9/site-packages/torch/utils/data/dataloader.py", line 1329, in _next_data
    idx, data = self._get_data()
  File "/home/rtcalumby/miniconda3/envs/fgdcc/lib/python3.9/site-packages/torch/utils/data/dataloader.py", line 1295, in _get_data
    success, data = self._try_get_data()
  File "/home/rtcalumby/miniconda3/envs/fgdcc/lib/python3.9/site-packages/torch/utils/data/dataloader.py", line 1146, in _try_get_data
    raise RuntimeError(f'DataLoader worker (pid(s) {pids_str}) exited unexpectedly') from e
RuntimeError: DataLoader worker (pid(s) 1542685) exited unexpectedly
terminate called after throwing an instance of 'terminate called after throwing an instance of 'c10::DistNetworkErrorc10::DistNetworkError'
'
  what():  Connection reset by peer
Exception raised from recvBytes at /opt/conda/conda-bld/pytorch_1712608885084/work/torch/csrc/distributed/c10d/Utils.hpp:672 (most recent call first):
frame #0: c10::Error::Error(c10::SourceLocation, std::string) + 0x57 (0x7efe9e80b897 in /home/rtcalumby/miniconda3/envs/fgdcc/lib/python3.9/site-packages/torch/lib/libc10.so)
frame #1: <unknown function> + 0x57c69fe (0x7efef7b7c9fe in /home/rtcalumby/miniconda3/envs/fgdcc/lib/python3.9/site-packages/torch/lib/libtorch_cpu.so)
frame #2: c10d::TCPStore::check(std::vector<std::string, std::allocator<std::string> > const&) + 0x2d8 (0x7efef7b78538 in /home/rtcalumby/miniconda3/envs/fgdcc/lib/python3.9/site-packages/torch/lib/libtorch_cpu.so)
frame #3: c10d::ProcessGroupNCCL::heartbeatMonitor() + 0x34d (0x7efe9fad96fd in /home/rtcalumby/miniconda3/envs/fgdcc/lib/python3.9/site-packages/torch/lib/libtorch_cuda.so)
frame #4: <unknown function> + 0xd3b65 (0x7eff00076b65 in /home/rtcalumby/miniconda3/envs/fgdcc/lib/python3.9/site-packages/torch/lib/../../../.././libstdc++.so.6)
frame #5: <unknown function> + 0x8609 (0x7eff08f27609 in /lib/x86_64-linux-gnu/libpthread.so.0)
frame #6: clone + 0x43 (0x7eff08cf2353 in /lib/x86_64-linux-gnu/libc.so.6)

  what():  Connection reset by peer
Exception raised from recvBytes at /opt/conda/conda-bld/pytorch_1712608885084/work/torch/csrc/distributed/c10d/Utils.hpp:672 (most recent call first):
frame #0: c10::Error::Error(c10::SourceLocation, std::string) + 0x57 (0x7f984ea31897 in /home/rtcalumby/miniconda3/envs/fgdcc/lib/python3.9/site-packages/torch/lib/libc10.so)
frame #1: <unknown function> + 0x57c69fe (0x7f98a7da29fe in /home/rtcalumby/miniconda3/envs/fgdcc/lib/python3.9/site-packages/torch/lib/libtorch_cpu.so)
frame #2: c10d::TCPStore::check(std::vector<std::string, std::allocator<std::string> > const&) + 0x2d8 (0x7f98a7d9e538 in /home/rtcalumby/miniconda3/envs/fgdcc/lib/python3.9/site-packages/torch/lib/libtorch_cpu.so)
frame #3: c10d::ProcessGroupNCCL::heartbeatMonitor() + 0x34d (0x7f984fcff6fd in /home/rtcalumby/miniconda3/envs/fgdcc/lib/python3.9/site-packages/torch/lib/libtorch_cuda.so)
frame #4: <unknown function> + 0xd3b65 (0x7f98b029cb65 in /home/rtcalumby/miniconda3/envs/fgdcc/lib/python3.9/site-packages/torch/lib/../../../.././libstdc++.so.6)
frame #5: <unknown function> + 0x8609 (0x7f98b914d609 in /lib/x86_64-linux-gnu/libpthread.so.0)
frame #6: clone + 0x43 (0x7f98b8f18353 in /lib/x86_64-linux-gnu/libc.so.6)

