INFO:root:called-params config/configs.yaml
INFO:root:loaded params...
INFO:root:{'k_means': {'K': 7806}, 'patches': {'N': [16, 32, 64, 80, 128]}, 'num_workers': 32, 'base_dir': '/home/rtcalumby/adam/luciano/PlantCLEF2025/PlantCLEF2025/', 'pretrained_path': 'pretrained_models/vit_base_patch14_reg4_dinov2_lvd142m_pc24_onlyclassifier_then_all/model_best.pth.tar', 'data': {'class_mapping': 'pretrained_models/class_mapping.txt', 'species_mapping': 'pretrained_models/species_id_to_name.txt', 'test_data': '/home/rtcalumby/adam/luciano/PlantCLEF2025/test_dataset/'}}
INFO:root:Running... (rank: 0/4)
INFO:root:Initialized (rank/world-size) 0/4
INFO:timm.models._helpers:Loaded state_dict_ema from checkpoint 'pretrained_models/vit_base_patch14_reg4_dinov2_lvd142m_pc24_onlyclassifier_then_all/model_best.pth.tar'
Test dataset created
Test dataset created
Test dataset created
Test dataset created
INFO:root:Image [1/2105]
Process Process-1:
Traceback (most recent call last):
  File "/home/rtcalumby/miniconda3/envs/fgdcc/lib/python3.9/multiprocessing/process.py", line 315, in _bootstrap
    self.run()
  File "/home/rtcalumby/miniconda3/envs/fgdcc/lib/python3.9/multiprocessing/process.py", line 108, in run
    self._target(*self._args, **self._kwargs)
  File "/home/rtcalumby/adam/luciano/PlantCLEF2025/PlantCLEF2025/main.py", line 44, in process_main
    app_main(args=params)
  File "/home/rtcalumby/adam/luciano/PlantCLEF2025/PlantCLEF2025/engine_baseline.py", line 116, in main
    x = batch.to(device, non_blocking=False)
AttributeError: 'list' object has no attribute 'to'
Process Process-2:
Traceback (most recent call last):
  File "/home/rtcalumby/miniconda3/envs/fgdcc/lib/python3.9/multiprocessing/process.py", line 315, in _bootstrap
    self.run()
  File "/home/rtcalumby/miniconda3/envs/fgdcc/lib/python3.9/multiprocessing/process.py", line 108, in run
    self._target(*self._args, **self._kwargs)
  File "/home/rtcalumby/adam/luciano/PlantCLEF2025/PlantCLEF2025/main.py", line 44, in process_main
    app_main(args=params)
  File "/home/rtcalumby/adam/luciano/PlantCLEF2025/PlantCLEF2025/engine_baseline.py", line 116, in main
    x = batch.to(device, non_blocking=False)
AttributeError: 'list' object has no attribute 'to'
Process Process-3:
Traceback (most recent call last):
  File "/home/rtcalumby/miniconda3/envs/fgdcc/lib/python3.9/multiprocessing/process.py", line 315, in _bootstrap
    self.run()
  File "/home/rtcalumby/miniconda3/envs/fgdcc/lib/python3.9/multiprocessing/process.py", line 108, in run
    self._target(*self._args, **self._kwargs)
  File "/home/rtcalumby/adam/luciano/PlantCLEF2025/PlantCLEF2025/main.py", line 44, in process_main
    app_main(args=params)
  File "/home/rtcalumby/adam/luciano/PlantCLEF2025/PlantCLEF2025/engine_baseline.py", line 116, in main
    x = batch.to(device, non_blocking=False)
AttributeError: 'list' object has no attribute 'to'
Process Process-4:
Traceback (most recent call last):
  File "/home/rtcalumby/miniconda3/envs/fgdcc/lib/python3.9/multiprocessing/process.py", line 315, in _bootstrap
    self.run()
  File "/home/rtcalumby/miniconda3/envs/fgdcc/lib/python3.9/multiprocessing/process.py", line 108, in run
    self._target(*self._args, **self._kwargs)
  File "/home/rtcalumby/adam/luciano/PlantCLEF2025/PlantCLEF2025/main.py", line 44, in process_main
    app_main(args=params)
  File "/home/rtcalumby/adam/luciano/PlantCLEF2025/PlantCLEF2025/engine_baseline.py", line 116, in main
    x = batch.to(device, non_blocking=False)
AttributeError: 'list' object has no attribute 'to'
terminate called after throwing an instance of 'terminate called after throwing an instance of 'c10::DistNetworkErrorc10::DistNetworkError'
'
  what():    what():  Connection reset by peer
Exception raised from recvBytes at /opt/conda/conda-bld/pytorch_1712608885084/work/torch/csrc/distributed/c10d/Utils.hpp:672 (most recent call first):
frame #0: c10::Error::Error(c10::SourceLocation, std::string) + 0x57 (0x7f44ce4db897 in /home/rtcalumby/miniconda3/envs/fgdcc/lib/python3.9/site-packages/torch/lib/libc10.so)
frame #1: <unknown function> + 0x57c69fe (0x7f452784c9fe in /home/rtcalumby/miniconda3/envs/fgdcc/lib/python3.9/site-packages/torch/lib/libtorch_cpu.so)
frame #2: c10d::TCPStore::check(std::vector<std::string, std::allocator<std::string> > const&) + 0x2d8 (0x7f4527848538 in /home/rtcalumby/miniconda3/envs/fgdcc/lib/python3.9/site-packages/torch/lib/libtorch_cpu.so)
frame #3: c10d::ProcessGroupNCCL::heartbeatMonitor() + 0x34d (0x7f44cf7a96fd in /home/rtcalumby/miniconda3/envs/fgdcc/lib/python3.9/site-packages/torch/lib/libtorch_cuda.so)
frame #4: <unknown function> + 0xd3b65 (0x7f452fd46b65 in /home/rtcalumby/miniconda3/envs/fgdcc/lib/python3.9/site-packages/torch/lib/../../../.././libstdc++.so.6)
frame #5: <unknown function> + 0x8609 (0x7f4538bf7609 in /lib/x86_64-linux-gnu/libpthread.so.0)
frame #6: clone + 0x43 (0x7f45389c2353 in /lib/x86_64-linux-gnu/libc.so.6)
Connection reset by peer
Exception raised from recvBytes at /opt/conda/conda-bld/pytorch_1712608885084/work/torch/csrc/distributed/c10d/Utils.hpp:672 (most recent call first):
frame #0: c10::Error::Error(c10::SourceLocation, std::string) + 0x57 (0x7f3fc6ffb897 in /home/rtcalumby/miniconda3/envs/fgdcc/lib/python3.9/site-packages/torch/lib/libc10.so)
frame #1: <unknown function> + 0x57c69fe (0x7f402036c9fe in /home/rtcalumby/miniconda3/envs/fgdcc/lib/python3.9/site-packages/torch/lib/libtorch_cpu.so)
frame #2: c10d::TCPStore::check(std::vector<std::string, std::allocator<std::string> > const&) + 0x2d8 (0x7f4020368538 in /home/rtcalumby/miniconda3/envs/fgdcc/lib/python3.9/site-packages/torch/lib/libtorch_cpu.so)
frame #3: c10d::ProcessGroupNCCL::heartbeatMonitor() + 0x34d (0x7f3fc82c96fd in /home/rtcalumby/miniconda3/envs/fgdcc/lib/python3.9/site-packages/torch/lib/libtorch_cuda.so)
frame #4: <unknown function> + 0xd3b65 (0x7f4028866b65 in /home/rtcalumby/miniconda3/envs/fgdcc/lib/python3.9/site-packages/torch/lib/../../../.././libstdc++.so.6)
frame #5: <unknown function> + 0x8609 (0x7f4031717609 in /lib/x86_64-linux-gnu/libpthread.so.0)
frame #6: clone + 0x43 (0x7f40314e2353 in /lib/x86_64-linux-gnu/libc.so.6)


terminate called after throwing an instance of 'c10::DistNetworkError'
  what():  Connection reset by peer
Exception raised from recvBytes at /opt/conda/conda-bld/pytorch_1712608885084/work/torch/csrc/distributed/c10d/Utils.hpp:672 (most recent call first):
frame #0: c10::Error::Error(c10::SourceLocation, std::string) + 0x57 (0x7f1efebc9897 in /home/rtcalumby/miniconda3/envs/fgdcc/lib/python3.9/site-packages/torch/lib/libc10.so)
frame #1: <unknown function> + 0x57c69fe (0x7f1f57f3a9fe in /home/rtcalumby/miniconda3/envs/fgdcc/lib/python3.9/site-packages/torch/lib/libtorch_cpu.so)
frame #2: c10d::TCPStore::check(std::vector<std::string, std::allocator<std::string> > const&) + 0x2d8 (0x7f1f57f36538 in /home/rtcalumby/miniconda3/envs/fgdcc/lib/python3.9/site-packages/torch/lib/libtorch_cpu.so)
frame #3: c10d::ProcessGroupNCCL::heartbeatMonitor() + 0x34d (0x7f1effe976fd in /home/rtcalumby/miniconda3/envs/fgdcc/lib/python3.9/site-packages/torch/lib/libtorch_cuda.so)
frame #4: <unknown function> + 0xd3b65 (0x7f1f60434b65 in /home/rtcalumby/miniconda3/envs/fgdcc/lib/python3.9/site-packages/torch/lib/../../../.././libstdc++.so.6)
frame #5: <unknown function> + 0x8609 (0x7f1f692e5609 in /lib/x86_64-linux-gnu/libpthread.so.0)
frame #6: clone + 0x43 (0x7f1f690b0353 in /lib/x86_64-linux-gnu/libc.so.6)

