INFO:root:called-params config/configs.yaml
INFO:root:loaded params...
{   'base_dir': '/home/rtcalumby/adam/luciano/PlantCLEF2025/PlantCLEF2025/',
    'data': {   'class_mapping': 'pretrained_models/class_mapping.txt',
                'species_mapping': 'pretrained_models/species_id_to_name.txt',
                'test_data': '/home/rtcalumby/adam/luciano/PlantCLEF2025/test_dataset/'},
    'k_means': {'K': 7806},
    'num_workers': 32,
    'patches': {'N': [16, 32, 64, 80, 128]},
    'pretrained_path': 'pretrained_models/vit_base_patch14_reg4_dinov2_lvd142m_pc24_onlyclassifier_then_all/model_best.pth.tar'}
INFO:root:Running... (rank: 0/4)
INFO:root:Initialized (rank/world-size) 0/4
Process Process-3:
Traceback (most recent call last):
  File "/home/rtcalumby/miniconda3/envs/fgdcc/lib/python3.9/multiprocessing/process.py", line 315, in _bootstrap
    self.run()
  File "/home/rtcalumby/miniconda3/envs/fgdcc/lib/python3.9/multiprocessing/process.py", line 108, in run
    self._target(*self._args, **self._kwargs)
  File "/home/rtcalumby/adam/luciano/PlantCLEF2025/PlantCLEF2025/main.py", line 44, in process_main
    app_main(args=params)
  File "/home/rtcalumby/adam/luciano/PlantCLEF2025/PlantCLEF2025/engine_baseline.py", line 57, in main
    model = model.to(device)
  File "/home/rtcalumby/miniconda3/envs/fgdcc/lib/python3.9/site-packages/torch/nn/modules/module.py", line 1173, in to
    return self._apply(convert)
  File "/home/rtcalumby/miniconda3/envs/fgdcc/lib/python3.9/site-packages/torch/nn/modules/module.py", line 779, in _apply
    module._apply(fn)
  File "/home/rtcalumby/miniconda3/envs/fgdcc/lib/python3.9/site-packages/torch/nn/modules/module.py", line 779, in _apply
    module._apply(fn)
  File "/home/rtcalumby/miniconda3/envs/fgdcc/lib/python3.9/site-packages/torch/nn/modules/module.py", line 804, in _apply
    param_applied = fn(param)
  File "/home/rtcalumby/miniconda3/envs/fgdcc/lib/python3.9/site-packages/torch/nn/modules/module.py", line 1159, in convert
    return t.to(
  File "/home/rtcalumby/miniconda3/envs/fgdcc/lib/python3.9/site-packages/torch/cuda/__init__.py", line 293, in _lazy_init
    torch._C._cuda_init()
RuntimeError: No CUDA GPUs are available
{   'base_dir': '/home/rtcalumby/adam/luciano/PlantCLEF2025/PlantCLEF2025/',
    'data': {   'class_mapping': 'pretrained_models/class_mapping.txt',
                'species_mapping': 'pretrained_models/species_id_to_name.txt',
                'test_data': '/home/rtcalumby/adam/luciano/PlantCLEF2025/test_dataset/'},
    'k_means': {'K': 7806},
    'num_workers': 32,
    'patches': {'N': [16, 32, 64, 80, 128]},
    'pretrained_path': 'pretrained_models/vit_base_patch14_reg4_dinov2_lvd142m_pc24_onlyclassifier_then_all/model_best.pth.tar'}
Process Process-4:
Traceback (most recent call last):
  File "/home/rtcalumby/miniconda3/envs/fgdcc/lib/python3.9/multiprocessing/process.py", line 315, in _bootstrap
    self.run()
  File "/home/rtcalumby/miniconda3/envs/fgdcc/lib/python3.9/multiprocessing/process.py", line 108, in run
    self._target(*self._args, **self._kwargs)
  File "/home/rtcalumby/adam/luciano/PlantCLEF2025/PlantCLEF2025/main.py", line 44, in process_main
    app_main(args=params)
  File "/home/rtcalumby/adam/luciano/PlantCLEF2025/PlantCLEF2025/engine_baseline.py", line 57, in main
    model = model.to(device)
  File "/home/rtcalumby/miniconda3/envs/fgdcc/lib/python3.9/site-packages/torch/nn/modules/module.py", line 1173, in to
    return self._apply(convert)
  File "/home/rtcalumby/miniconda3/envs/fgdcc/lib/python3.9/site-packages/torch/nn/modules/module.py", line 779, in _apply
    module._apply(fn)
  File "/home/rtcalumby/miniconda3/envs/fgdcc/lib/python3.9/site-packages/torch/nn/modules/module.py", line 779, in _apply
    module._apply(fn)
  File "/home/rtcalumby/miniconda3/envs/fgdcc/lib/python3.9/site-packages/torch/nn/modules/module.py", line 804, in _apply
    param_applied = fn(param)
  File "/home/rtcalumby/miniconda3/envs/fgdcc/lib/python3.9/site-packages/torch/nn/modules/module.py", line 1159, in convert
    return t.to(
  File "/home/rtcalumby/miniconda3/envs/fgdcc/lib/python3.9/site-packages/torch/cuda/__init__.py", line 293, in _lazy_init
    torch._C._cuda_init()
RuntimeError: No CUDA GPUs are available
{   'base_dir': '/home/rtcalumby/adam/luciano/PlantCLEF2025/PlantCLEF2025/',
    'data': {   'class_mapping': 'pretrained_models/class_mapping.txt',
                'species_mapping': 'pretrained_models/species_id_to_name.txt',
                'test_data': '/home/rtcalumby/adam/luciano/PlantCLEF2025/test_dataset/'},
    'k_means': {'K': 7806},
    'num_workers': 32,
    'patches': {'N': [16, 32, 64, 80, 128]},
    'pretrained_path': 'pretrained_models/vit_base_patch14_reg4_dinov2_lvd142m_pc24_onlyclassifier_then_all/model_best.pth.tar'}
INFO:timm.models._helpers:Loaded state_dict_ema from checkpoint 'pretrained_models/vit_base_patch14_reg4_dinov2_lvd142m_pc24_onlyclassifier_then_all/model_best.pth.tar'
Process Process-2:
Traceback (most recent call last):
  File "/home/rtcalumby/miniconda3/envs/fgdcc/lib/python3.9/multiprocessing/process.py", line 315, in _bootstrap
    self.run()
  File "/home/rtcalumby/miniconda3/envs/fgdcc/lib/python3.9/multiprocessing/process.py", line 108, in run
    self._target(*self._args, **self._kwargs)
  File "/home/rtcalumby/adam/luciano/PlantCLEF2025/PlantCLEF2025/main.py", line 44, in process_main
    app_main(args=params)
  File "/home/rtcalumby/adam/luciano/PlantCLEF2025/PlantCLEF2025/engine_baseline.py", line 57, in main
    model = model.to(device)
  File "/home/rtcalumby/miniconda3/envs/fgdcc/lib/python3.9/site-packages/torch/nn/modules/module.py", line 1173, in to
    return self._apply(convert)
  File "/home/rtcalumby/miniconda3/envs/fgdcc/lib/python3.9/site-packages/torch/nn/modules/module.py", line 779, in _apply
    module._apply(fn)
  File "/home/rtcalumby/miniconda3/envs/fgdcc/lib/python3.9/site-packages/torch/nn/modules/module.py", line 779, in _apply
    module._apply(fn)
  File "/home/rtcalumby/miniconda3/envs/fgdcc/lib/python3.9/site-packages/torch/nn/modules/module.py", line 804, in _apply
    param_applied = fn(param)
  File "/home/rtcalumby/miniconda3/envs/fgdcc/lib/python3.9/site-packages/torch/nn/modules/module.py", line 1159, in convert
    return t.to(
  File "/home/rtcalumby/miniconda3/envs/fgdcc/lib/python3.9/site-packages/torch/cuda/__init__.py", line 293, in _lazy_init
    torch._C._cuda_init()
RuntimeError: No CUDA GPUs are available
{   'base_dir': '/home/rtcalumby/adam/luciano/PlantCLEF2025/PlantCLEF2025/',
    'data': {   'class_mapping': 'pretrained_models/class_mapping.txt',
                'species_mapping': 'pretrained_models/species_id_to_name.txt',
                'test_data': '/home/rtcalumby/adam/luciano/PlantCLEF2025/test_dataset/'},
    'k_means': {'K': 7806},
    'num_workers': 32,
    'patches': {'N': [16, 32, 64, 80, 128]},
    'pretrained_path': 'pretrained_models/vit_base_patch14_reg4_dinov2_lvd142m_pc24_onlyclassifier_then_all/model_best.pth.tar'}
Test dataset created
INFO:root:Image [1/2105]
Process Process-1:
Traceback (most recent call last):
  File "/home/rtcalumby/miniconda3/envs/fgdcc/lib/python3.9/multiprocessing/process.py", line 315, in _bootstrap
    self.run()
  File "/home/rtcalumby/miniconda3/envs/fgdcc/lib/python3.9/multiprocessing/process.py", line 108, in run
    self._target(*self._args, **self._kwargs)
  File "/home/rtcalumby/adam/luciano/PlantCLEF2025/PlantCLEF2025/main.py", line 44, in process_main
    app_main(args=params)
  File "/home/rtcalumby/adam/luciano/PlantCLEF2025/PlantCLEF2025/engine_baseline.py", line 105, in main
    x = batch.to(device, non_blocking=True)
AttributeError: 'list' object has no attribute 'to'
