INFO:root:called-params config/feature_extraction.yaml
INFO:root:loaded params...
INFO:root:{'num_workers': 64, 'base_dir': '/home/rtcalumby/adam/luciano/PlantCLEF2025/PlantCLEF2025/', 'pretrained_path': 'pretrained_models/vit_base_patch14_reg4_dinov2_lvd142m_pc24_onlyclassifier_then_all/model_best.pth.tar', 'data': {'class_mapping': 'pretrained_models/class_mapping.txt', 'species_mapping': 'pretrained_models/species_id_to_name.txt', 'train_data': '/home/rtcalumby/adam/luciano/PlantCLEF2025/images_max_side_800/', 'output_dir': '/home/rtcalumby/adam/luciano/PlantCLEF2025/cached_features/'}}
INFO:root:Running... (rank: 0/8)
INFO:root:Initialized (rank/world-size) 0/8
INFO:timm.models._helpers:Loaded state_dict_ema from checkpoint 'pretrained_models/vit_base_patch14_reg4_dinov2_lvd142m_pc24_onlyclassifier_then_all/model_best.pth.tar'
Train dataset created
Train dataset created
Train dataset created
Train dataset created
Train dataset created
Train dataset created
Train dataset created
Train dataset created
INFO:root:Iteration [1/1408033]
Rank, 0 Cache keys 1687
INFO:root:Total features gathered 16384, problem size: 1408033
Process Process-1:
Traceback (most recent call last):
  File "/home/rtcalumby/miniconda3/envs/fgdcc/lib/python3.9/multiprocessing/process.py", line 315, in _bootstrap
    self.run()
  File "/home/rtcalumby/miniconda3/envs/fgdcc/lib/python3.9/multiprocessing/process.py", line 108, in run
    self._target(*self._args, **self._kwargs)
  File "/home/rtcalumby/adam/luciano/PlantCLEF2025/PlantCLEF2025/main_feature_extraction.py", line 44, in process_main
    app_main(args=params)
  File "/home/rtcalumby/adam/luciano/PlantCLEF2025/PlantCLEF2025/engine_feature_extraction.py", line 109, in main
    assert total == dataset_length, 'Cache not compatible, corrupted or missing'
AssertionError: Cache not compatible, corrupted or missing
Rank, 2 Cache keys 1656
Rank, 7 Cache keys 1657
Rank, 5 Cache keys 1660
Rank, 6 Cache keys 1670
Rank, 1 Cache keys 1681
Rank, 4 Cache keys 1674
Rank, 3 Cache keys 1672
